Workbook
Name aporte: Simulador!$E$19
Name patrimonio: Simulador!$E$22
Name qtd_anos: Simulador!$E$20
Name rendimento_carteira: Simulador!$E$15
Name salario: Simulador!$E$14
Name sugestao_investimento: Simulador!$E$16
Name taxa_mensal: Simulador!$E$21

Sheet Simulador
B11: Preencha os campos em bege. O restante é calculado.
B13: CONFIGURAÇÕES
B14: Salário | E14: 3400
B15: Rendimento carteira | E15: 0.006
B16: Sugestão de investimento (30% do salário) | E16: =E14*30% -> 1020
B18: INVESTIMENTO MENSAL
B19: Quanto investir por mês? | E19: 500
B20: Por quantos anos investir? | E20: 10
B21: Taxa de rendimento mensal? | E21: 0.01079
B22: Patrimônio acumulado? | E22: =FV(taxa_mensal,qtd_anos*12,aporte*-1) -> 121642.11
B23: Dividendos mensais? | E23: =patrimonio*rendimento_carteira -> 729.85264
B25: CENÁRIOS
B26: Prazo | C26: Total investido | D26: Patrimônio acumulado | E26: Dividendo/mês
A27: 2 | B27: Quanto em 2 anos? | C27: =A27*aporte*12 -> 12000 | D27: =FV($E$21,$A27*12,$E$19*-1) -> 13613.814 | E27: =D27*rendimento_carteira -> 81.682882
A28: 5 | B28: Quanto em 5 anos? | C28: =A28*aporte*12 -> 30000 | D28: =FV($E$21,$A28*12,$E$19*-1) -> 41888.457 | E28: =D28*rendimento_carteira -> 251.33074
A29: 10 | B29: Quanto em 10 anos? | C29: =A29*aporte*12 -> 60000 | D29: =FV($E$21,$A29*12,$E$19*-1) -> 121642.11 | E29: =D29*rendimento_carteira -> 729.85264
A30: 20 | B30: Quanto em 20 anos? | C30: =A30*aporte*12 -> 120000 | D30: =FV($E$21,$A30*12,$E$19*-1) -> 562599.2 | E30: =D30*rendimento_carteira -> 3375.5952
A31: 30 | B31: Quanto em 30 anos? | C31: =A31*aporte*12 -> 180000 | D31: =FV($E$21,$A31*12,$E$19*-1) -> 2161084.8 | E31: =D31*rendimento_carteira -> 12966.509
B45: SELECIONE O SEU PERFIL INVESTIDOR | D45: Moderado
B46: VALOR A SER INVESTIDO POR MÊS | D46: =aporte -> 500
B48: Tipo de FII | D48: Percentual sugerido | E48: Valores
B49: PAPEL | D49: =VLOOKUP($D$45&"-"&B49,'Tabela de apoio para perfis e %'!$B:$E,4,FALSE) -> 0.32 | E49: =D49*$D$46 -> 160
B50: TIJOLO | D50: =VLOOKUP($D$45&"-"&B50,'Tabela de apoio para perfis e %'!$B:$E,4,FALSE) -> 0.35 | E50: =D50*$D$46 -> 175
B51: HÍBRIDOS | D51: =VLOOKUP($D$45&"-"&B51,'Tabela de apoio para perfis e %'!$B:$E,4,FALSE) -> 0.08 | E51: =D51*$D$46 -> 40
B52: FOFs | D52: =VLOOKUP($D$45&"-"&B52,'Tabela de apoio para perfis e %'!$B:$E,4,FALSE) -> 0.05 | E52: =D52*$D$46 -> 25
B53: DESENVOLVIMENTO | D53: =VLOOKUP($D$45&"-"&B53,'Tabela de apoio para perfis e %'!$B:$E,4,FALSE) -> 0.1 | E53: =D53*$D$46 -> 50
B54: HOTELARIAS | D54: =VLOOKUP($D$45&"-"&B54,'Tabela de apoio para perfis e %'!$B:$E,4,FALSE) -> 0.1 | E54: =D54*$D$46 -> 50
B80: Período | C80: Patrimônio Acumulado | D80: Patrimônio Acumulado
B81: 0 anos | C81: 0 | D81: 0
B82: 2 anos | C82: =FV(taxa_mensal,$A27*12,aporte*-1) -> 13613.814 | D82: =FV(taxa_mensal,$A27*12,aporte*-1) -> 13613.814
B83: 5 anos | C83: =FV(taxa_mensal,$A28*12,aporte*-1) -> 41888.457 | D83: =FV(taxa_mensal,$A28*12,aporte*-1) -> 41888.457
B84: 10 anos | C84: =FV(taxa_mensal,$A29*12,aporte*-1) -> 121642.11 | D84: =FV(taxa_mensal,$A29*12,aporte*-1) -> 121642.11
B85: 20 anos | C85: =FV(taxa_mensal,$A30*12,aporte*-1) -> 562599.2 | D85: =FV(taxa_mensal,$A30*12,aporte*-1) -> 562599.2
B86: 30 anos | C86: =FV(taxa_mensal,$A31*12,aporte*-1) -> 2161084.8 | D86: =FV(taxa_mensal,$A31*12,aporte*-1) -> 2161084.8
B88: Período | C88: Dividendos Mensais | D88: Dividendos Mensais
B89: 0 anos | C89: 0 | D89: 0
B90: 2 anos | C90: =D27*rendimento_carteira -> 81.682882 | D90: =D27*rendimento_carteira -> 81.682882
B91: 5 anos | C91: =D28*rendimento_carteira -> 251.33074 | D91: =D28*rendimento_carteira -> 251.33074
B92: 10 anos | C92: =D29*rendimento_carteira -> 729.85264 | D92: =D29*rendimento_carteira -> 729.85264
B93: 20 anos | C93: =D30*rendimento_carteira -> 3375.5952 | D93: =D30*rendimento_carteira -> 3375.5952
...

Sheet Tabela de apoio para perfis e %
B2: CHAVE | C2: Perfil | D2: TIPO DE FII | E2: %
B3: =C3&"-"&D3 -> Conservador-PAPEL | C3: Conservador | D3: PAPEL | E3: 0.3
B4: =C4&"-"&D4 -> Conservador-TIJOLO | C4: Conservador | D4: TIJOLO | E4: 0.5 | G4: Moderado-TIJOLO | H4: =VLOOKUP(G4,$B:$E,4,FALSE) -> 0.35
B5: =C5&"-"&D5 -> Conservador-HÍBRIDOS | C5: Conservador | D5: HÍBRIDOS | E5: 0.1
B6: =C6&"-"&D6 -> Conservador-FOFs | C6: Conservador | D6: FOFs | E6: 0.1
B7: =C7&"-"&D7 -> Conservador-DESENVOLVIMENTO | C7: Conservador | D7: DESENVOLVIMENTO | E7: 0
B8: =C8&"-"&D8 -> Conservador-HOTELARIAS | C8: Conservador | D8: HOTELARIAS | E8: 0
B9: =C9&"-"&D9 -> Moderado-PAPEL | C9: Moderado | D9: PAPEL | E9: 0.32
B10: =C10&"-"&D10 -> Moderado-TIJOLO | C10: Moderado | D10: TIJOLO | E10: 0.35
B11: =C11&"-"&D11 -> Moderado-HÍBRIDOS | C11: Moderado | D11: HÍBRIDOS | E11: 0.08
B12: =C12&"-"&D12 -> Moderado-FOFs | C12: Moderado | D12: FOFs | E12: 0.05
B13: =C13&"-"&D13 -> Moderado-DESENVOLVIMENTO | C13: Moderado | D13: DESENVOLVIMENTO | E13: 0.1
B14: =C14&"-"&D14 -> Moderado-HOTELARIAS | C14: Moderado | D14: HOTELARIAS | E14: 0.1
B15: =C15&"-"&D15 -> Agressivo-PAPEL | C15: Agressivo | D15: PAPEL | E15: 0.5
B16: =C16&"-"&D16 -> Agressivo-TIJOLO | C16: Agressivo | D16: TIJOLO | E16: 0.1
... B20: =C20&"-"&D20 -> Agressivo-HOTELARIAS | C20: Agressivo | D20: HOTELARIAS | E20: 0.1

Sheet Pergunta de negócio
B2: Objetivo: Criar um simulador simples de investimento
B4: Quanto investir por mês?
B5: Por quantos anos tem que investir?
B6: Qual a taxa de rendimento mensal?
B8: Quanto de patrimônio acumulado?
B9: Quanto são os dividendos mensais?
B12: Intervalos nomeados
B13: Tabelas de apoio
